const e='# Module 11: Error and Exception Handling - Lesson 3: The `else` and `finally` Clauses\n\nIn addition to the `try` and `except` clauses, Python\'s exception handling mechanism provides two more optional clauses: `else` and `finally`. These clauses offer more fine-grained control over what happens during and after the execution of a `try...except` block.\n\n**1. The `else` Clause**\n\nThe `else` clause, when used with a `try...except` block, contains code that should be executed **if and only if the `try` block does not raise any exceptions**.\n\n**Syntax:**\n\n```python\ntry:\n    # Code that might raise an exception\n    # ...\nexcept SomeExceptionType:\n    # Code to handle SomeExceptionType if it occurs in the try block\n    # ...\nelse:\n    # Code that executes ONLY if NO exception occurred in the try block.\n    # This is a good place for code that depends on the successful completion\n    # of the try block.\n    # ...\n```\n\n**How it Works with `else`:**\n\n1.  The `try` block is executed.\n2.  **If an exception occurs in the `try` block**: Python skips the rest of the `try` block, looks for a matching `except` block. If found, the `except` block is executed. The `else` block is **skipped**.\n3.  **If no exception occurs in the `try` block**: The entire `try` block completes successfully. Python then executes the `else` block. The `except` block(s) are skipped.\n\n**Why Use the `else` Clause?**\n\nThe `else` clause helps to clearly separate the code that might raise an exception (in the `try` block) from the code that should run only if the `try` block was successful. This can improve readability because it reduces the amount of code in the `try` block itself. Any code in the `else` block is guaranteed not to have been the source of an exception that would be caught by the preceding `except` clauses.\n\n**Example using `else`:**\n\nLet\'s refine our division example:\n\n```python\ndef safe_divide_with_else(numerator, denominator):\n    print(f"\\nAttempting to divide {numerator} by {denominator}...")\n    try:\n        result = numerator / denominator # This is the operation that might fail\n    except ZeroDivisionError:\n        print("Error: Cannot divide by zero!")\n    except TypeError:\n        print("Error: Both numerator and denominator must be numbers.")\n    else:\n        # This block executes ONLY if the division was successful (no ZeroDivisionError or TypeError)\n        print(f"Division successful! The result is: {result}")\n        # Further operations that depend on a valid \'result\' can go here\n        if result > 10:\n            print("The result is greater than 10.")\n        return result\n\n# Test cases\nsafe_divide_with_else(100, 5)    # Successful, else block runs\nsafe_divide_with_else(10, 0)     # ZeroDivisionError, else block is skipped\nsafe_divide_with_else(20, "2")   # TypeError, else block is skipped\nsafe_divide_with_else(10, 4)     # Successful, else block runs\n```\n\n**Output:**\n```\nAttempting to divide 100 by 5...\nDivision successful! The result is: 20.0\nThe result is greater than 10.\n\nAttempting to divide 10 by 0...\nError: Cannot divide by zero!\n\nAttempting to divide 20 by 2...\nError: Both numerator and denominator must be numbers.\n\nAttempting to divide 10 by 4...\nDivision successful! The result is: 2.5\n```\nIn this example, the message "Division successful!" and subsequent checks on `result` are only printed if the division in the `try` block completes without raising `ZeroDivisionError` or `TypeError`.\n\n**2. The `finally` Clause**\n\nThe `finally` clause, when used with a `try...except` (and optionally `else`) block, contains code that **will always be executed**, regardless of whether an exception occurred in the `try` block or not, and whether any `except` or `else` blocks were executed.\n\n**Syntax:**\n\n```python\ntry:\n    # Code that might raise an exception\n    # ...\nexcept SomeExceptionType:\n    # Handler for SomeExceptionType\n    # ...\nelse: # Optional\n    # Executes if no exception in try block\n    # ...\nfinally:\n    # Code in this block is ALWAYS executed.\n    # This is typically used for cleanup actions (e.g., closing files, releasing resources).\n    # ...\n```\n\n**How it Works with `finally`:**\n\n*   The `try` block is executed.\n*   **If an exception occurs**: Python looks for a matching `except` block. If found, it\'s executed. **Then, the `finally` block is executed.** If no matching `except` is found, the exception propagates up, but **the `finally` block is still executed before the propagation continues**.\n*   **If no exception occurs**: The `try` block completes. If there\'s an `else` block, it\'s executed. **Then, the `finally` block is executed.**\n*   **If an `except` or `else` block raises a new exception or re-raises an exception**: The `finally` block is **still executed** before that new/re-raised exception propagates.\n*   **If there\'s a `return`, `break`, or `continue` statement in the `try`, `except`, or `else` block that would cause control to leave the `try...finally` structure**: The `finally` block is **still executed just before** control actually leaves.\n\n**Why Use the `finally` Clause?**\n\nThe primary use of the `finally` clause is for **cleanup actions** that must be performed under all circumstances. This includes:\n*   Closing files (though the `with` statement is preferred for this specific task).\n*   Releasing locks or other acquired resources (e.g., network connections, database connections).\n*   Resetting states or performing other cleanup tasks.\n\n**Example using `finally` (Conceptual File Handling - `with` is better for files):**\n\n```python\ndef process_file_conceptually(filepath):\n    f = None # Initialize f outside try so it\'s accessible in finally\n    try:\n        print(f"\\nAttempting to open and process file: {filepath}")\n        f = open(filepath, "r", encoding="utf-8")\n        content = f.read()\n        print(f"File content has {len(content)} characters.")\n        # Simulate an error for one case\n        if "error" in filepath:\n            raise ValueError("Simulated error during file processing!")\n        print("File processed successfully.")\n        \n    except FileNotFoundError:\n        print(f"Error: File \rások{filepath}" not found.")\n    except ValueError as ve:\n        print(f"ValueError during processing: {ve}")\n    except Exception as e:\n        print(f"An unexpected error occurred: {e}")\n    else:\n        print("No exceptions occurred during file processing in the try block.")\n    finally:\n        # This block ALWAYS executes\n        print("Executing finally block...")\n        if f and not f.closed:\n            print(f"Closing file: {filepath}")\n            f.close()\n        else:\n            print(f"File \rások{filepath}" was not opened or already closed.")\n\n# Create dummy files for testing\nwith open("data_ok.txt", "w") as temp_f: temp_f.write("Some good data.")\nwith open("data_error.txt", "w") as temp_f: temp_f.write("Data that will cause an error.")\n\nprocess_file_conceptually("data_ok.txt")\nprocess_file_conceptually("non_existent_file.txt")\nprocess_file_conceptually("data_error.txt")\n```\n\n**Output (Illustrative):**\n```\nAttempting to open and process file: data_ok.txt\nFile content has 15 characters.\nFile processed successfully.\nNo exceptions occurred during file processing in the try block.\nExecuting finally block...\nClosing file: data_ok.txt\n\nAttempting to open and process file: non_existent_file.txt\nError: File non_existent_file.txt not found.\nExecuting finally block...\nFile non_existent_file.txt was not opened or already closed.\n\nAttempting to open and process file: data_error.txt\nFile content has 29 characters.\nValueError during processing: Simulated error during file processing!\nExecuting finally block...\nClosing file: data_error.txt\n```\nNotice how the "Executing finally block..." message and the file closing logic run in all three scenarios.\n\n**Combining `try`, `except`, `else`, and `finally`**\n\nYou can use all four clauses together. The order is always `try`, then one or more `except` clauses, then an optional `else` clause, and finally an optional `finally` clause.\n\n```python\ntry:\n    # Risky operation\n    print("In try block")\n    x = int(input("Enter a number: "))\n    result = 100 / x\nexcept ValueError:\n    print("In ValueError except block: Not a valid number!")\nexcept ZeroDivisionError:\n    print("In ZeroDivisionError except block: Cannot divide by zero!")\nelse:\n    # Executes if try completes without any exception\n    print("In else block: No errors occurred.")\n    print(f"Result is: {result}")\nfinally:\n    # Always executes\n    print("In finally block: This always runs, e.g., for cleanup.")\n\nprint("Program continues...")\n```\n\n**Test this combined block with different inputs:**\n*   Enter `5`: `try` -> `else` -> `finally`\n*   Enter `0`: `try` (ZeroDivisionError) -> `except ZeroDivisionError` -> `finally`\n*   Enter `abc`: `try` (ValueError) -> `except ValueError` -> `finally`\n\n**When `finally` is Crucial**\n\nThe `finally` block is particularly important when an exception might be raised that you don\'t explicitly handle with an `except` clause, or when an `except` or `else` block itself might raise an exception. The `finally` clause guarantees that cleanup code runs before the program terminates or the exception propagates further.\n\n**Relationship with the `with` Statement**\n\nFor managing resources like files, network connections, or locks, the `with` statement (context manager protocol) is often a more Pythonic and cleaner alternative to using `try...finally` for resource deallocation. The `with` statement automatically handles the acquisition and release of resources, ensuring that cleanup methods (like `file.close()`) are called even if errors occur.\n\n```python\n# Using \'with\' for file handling (preferred)\ntry:\n    with open("my_file.txt", "w") as f:\n        f.write("Hello with \'with\'!")\n        # If an error occurs here, f.close() is still guaranteed by \'with\'\nexcept IOError as e:\n    print(f"IOError: {e}")\n# No explicit f.close() or finally needed for closing the file here.\n```\nThe `with` statement essentially encapsulates the logic often found in a `try...finally` block for resource management.\n\n**Conclusion**\n\nThe `else` and `finally` clauses provide additional control and clarity in Python\'s exception handling:\n\n*   **`else` block**: Executes if the `try` block completes successfully (no exceptions). Useful for code that should only run if the `try` part was error-free.\n*   **`finally` block**: Always executes, regardless of what happened in the `try`, `except`, or `else` blocks. Essential for cleanup actions that must occur no matter what.\n\nUnderstanding how to use these clauses effectively allows you to write more robust and maintainable Python code that can handle errors gracefully and manage resources properly. In the next lesson, we\'ll learn how to raise exceptions deliberately using the `raise` statement.\n';export{e as default};
